[32m2025-08-13 11:12:48 +0900[0m - dagster - [34mDEBUG[0m - __ASSET_JOB - d8089261-5e76-4c17-b44a-a6a2e26e731c - 50988 - LOGS_CAPTURED - Started capturing logs in process (pid: 50988).
[32m2025-08-13 11:12:48 +0900[0m - dagster - [34mDEBUG[0m - __ASSET_JOB - d8089261-5e76-4c17-b44a-a6a2e26e731c - 50988 - processed_data - STEP_START - Started execution of step "processed_data".
[32m2025-08-13 11:12:48 +0900[0m - dagster - [34mERROR[0m - [31m__ASSET_JOB - d8089261-5e76-4c17-b44a-a6a2e26e731c - 50988 - processed_data - STEP_FAILURE - Execution of step "processed_data" failed.

dagster._core.errors.DagsterExecutionStepExecutionError: Error occurred while executing op "processed_data"::

KeyError: 'age'

Stack Trace:
  File "/Users/60hertz/Library/CloudStorage/OneDrive-·Ñâ·Öµ·Ü®·Ñâ·Ö≥·Ñê·Öµ·Ñí·Ö¶·ÑÖ·Ö≥·Ñé·Ö≥·Ñå·ÖÆ·Ñâ·Öµ·Ü®·Ñí·Ö¨·Ñâ·Ö°/04. ·ÑÄ·Öµ·Ñê·Ö°/03. Github/dev-tools-study/dagster/code/dagster-quickstart/.venv/lib/python3.12/site-packages/dagster/_core/execution/plan/utils.py", line 57, in op_execution_error_boundary
    yield
  File "/Users/60hertz/Library/CloudStorage/OneDrive-·Ñâ·Öµ·Ü®·Ñâ·Ö≥·Ñê·Öµ·Ñí·Ö¶·ÑÖ·Ö≥·Ñé·Ö≥·Ñå·ÖÆ·Ñâ·Öµ·Ü®·Ñí·Ö¨·Ñâ·Ö°/04. ·ÑÄ·Öµ·Ñê·Ö°/03. Github/dev-tools-study/dagster/code/dagster-quickstart/.venv/lib/python3.12/site-packages/dagster/_utils/__init__.py", line 392, in iterate_with_context
    next_output = next(iterator)
                  ^^^^^^^^^^^^^^
  File "/Users/60hertz/Library/CloudStorage/OneDrive-·Ñâ·Öµ·Ü®·Ñâ·Ö≥·Ñê·Öµ·Ñí·Ö¶·ÑÖ·Ö≥·Ñé·Ö≥·Ñå·ÖÆ·Ñâ·Öµ·Ü®·Ñí·Ö¨·Ñâ·Ö°/04. ·ÑÄ·Öµ·Ñê·Ö°/03. Github/dev-tools-study/dagster/code/dagster-quickstart/.venv/lib/python3.12/site-packages/dagster/_core/execution/plan/compute_generator.py", line 137, in _coerce_op_compute_fn_to_iterator
    result = invoke_compute_fn(
             ^^^^^^^^^^^^^^^^^^
  File "/Users/60hertz/Library/CloudStorage/OneDrive-·Ñâ·Öµ·Ü®·Ñâ·Ö≥·Ñê·Öµ·Ñí·Ö¶·ÑÖ·Ö≥·Ñé·Ö≥·Ñå·ÖÆ·Ñâ·Öµ·Ü®·Ñí·Ö¨·Ñâ·Ö°/04. ·ÑÄ·Öµ·Ñê·Ö°/03. Github/dev-tools-study/dagster/code/dagster-quickstart/.venv/lib/python3.12/site-packages/dagster/_core/execution/plan/compute_generator.py", line 117, in invoke_compute_fn
    return fn(context, **args_to_pass) if context_arg_provided else fn(**args_to_pass)
                                                                    ^^^^^^^^^^^^^^^^^^
  File "/Users/60hertz/Library/CloudStorage/OneDrive-·Ñâ·Öµ·Ü®·Ñâ·Ö≥·Ñê·Öµ·Ñí·Ö¶·ÑÖ·Ö≥·Ñé·Ö≥·Ñå·ÖÆ·Ñâ·Öµ·Ü®·Ñí·Ö¨·Ñâ·Ö°/04. ·ÑÄ·Öµ·Ñê·Ö°/03. Github/dev-tools-study/dagster/code/dagster-quickstart/src/dagster_quickstart/defs/assets.py", line 12, in processed_data
    df["age"], bins=[0, 30, 40, 100], labels=["Young", "Middle", "Senior"]
    ~~^^^^^^^
  File "/Users/60hertz/Library/CloudStorage/OneDrive-·Ñâ·Öµ·Ü®·Ñâ·Ö≥·Ñê·Öµ·Ñí·Ö¶·ÑÖ·Ö≥·Ñé·Ö≥·Ñå·ÖÆ·Ñâ·Öµ·Ü®·Ñí·Ö¨·Ñâ·Ö°/04. ·ÑÄ·Öµ·Ñê·Ö°/03. Github/dev-tools-study/dagster/code/dagster-quickstart/.venv/lib/python3.12/site-packages/pandas/core/frame.py", line 4107, in __getitem__
    indexer = self.columns.get_loc(key)
              ^^^^^^^^^^^^^^^^^^^^^^^^^
  File "/Users/60hertz/Library/CloudStorage/OneDrive-·Ñâ·Öµ·Ü®·Ñâ·Ö≥·Ñê·Öµ·Ñí·Ö¶·ÑÖ·Ö≥·Ñé·Ö≥·Ñå·ÖÆ·Ñâ·Öµ·Ü®·Ñí·Ö¨·Ñâ·Ö°/04. ·ÑÄ·Öµ·Ñê·Ö°/03. Github/dev-tools-study/dagster/code/dagster-quickstart/.venv/lib/python3.12/site-packages/pandas/core/indexes/base.py", line 3819, in get_loc
    raise KeyError(key) from err

The above exception was caused by the following exception:
KeyError: 'age'

Stack Trace:
  File "/Users/60hertz/Library/CloudStorage/OneDrive-·Ñâ·Öµ·Ü®·Ñâ·Ö≥·Ñê·Öµ·Ñí·Ö¶·ÑÖ·Ö≥·Ñé·Ö≥·Ñå·ÖÆ·Ñâ·Öµ·Ü®·Ñí·Ö¨·Ñâ·Ö°/04. ·ÑÄ·Öµ·Ñê·Ö°/03. Github/dev-tools-study/dagster/code/dagster-quickstart/.venv/lib/python3.12/site-packages/pandas/core/indexes/base.py", line 3812, in get_loc
    return self._engine.get_loc(casted_key)
           ^^^^^^^^^^^^^^^^^^^^^^^^^^^^^^^^
  File "pandas/_libs/index.pyx", line 167, in pandas._libs.index.IndexEngine.get_loc
  File "pandas/_libs/index.pyx", line 196, in pandas._libs.index.IndexEngine.get_loc
  File "pandas/_libs/hashtable_class_helper.pxi", line 7088, in pandas._libs.hashtable.PyObjectHashTable.get_item
  File "pandas/_libs/hashtable_class_helper.pxi", line 7096, in pandas._libs.hashtable.PyObjectHashTable.get_item
[0m
